[2022-10-04 17:56:11,327] {taskinstance.py:1032} INFO - Dependencies all met for <TaskInstance: data_ingestion_gcs_dag.local_to_gcs_task manual__2022-10-04T17:55:58.781085+00:00 [queued]>
[2022-10-04 17:56:11,348] {taskinstance.py:1032} INFO - Dependencies all met for <TaskInstance: data_ingestion_gcs_dag.local_to_gcs_task manual__2022-10-04T17:55:58.781085+00:00 [queued]>
[2022-10-04 17:56:11,348] {taskinstance.py:1238} INFO - 
--------------------------------------------------------------------------------
[2022-10-04 17:56:11,349] {taskinstance.py:1239} INFO - Starting attempt 1 of 2
[2022-10-04 17:56:11,349] {taskinstance.py:1240} INFO - 
--------------------------------------------------------------------------------
[2022-10-04 17:56:11,370] {taskinstance.py:1259} INFO - Executing <Task(PythonOperator): local_to_gcs_task> on 2022-10-04 17:55:58.781085+00:00
[2022-10-04 17:56:11,382] {standard_task_runner.py:52} INFO - Started process 3006 to run task
[2022-10-04 17:56:11,387] {standard_task_runner.py:76} INFO - Running: ['***', 'tasks', 'run', 'data_ingestion_gcs_dag', 'local_to_gcs_task', 'manual__2022-10-04T17:55:58.781085+00:00', '--job-id', '21', '--raw', '--subdir', 'DAGS_FOLDER/data_ingestion_gcs_dag.py', '--cfg-path', '/tmp/tmpgz5x1rq9', '--error-file', '/tmp/tmp7rpzu8m9']
[2022-10-04 17:56:11,388] {standard_task_runner.py:77} INFO - Job 21: Subtask local_to_gcs_task
[2022-10-04 17:56:11,482] {logging_mixin.py:109} INFO - Running <TaskInstance: data_ingestion_gcs_dag.local_to_gcs_task manual__2022-10-04T17:55:58.781085+00:00 [running]> on host 3adc7691bbaa
[2022-10-04 17:56:11,571] {taskinstance.py:1426} INFO - Exporting the following env vars:
AIRFLOW_CTX_DAG_OWNER=***
AIRFLOW_CTX_DAG_ID=data_ingestion_gcs_dag
AIRFLOW_CTX_TASK_ID=local_to_gcs_task
AIRFLOW_CTX_EXECUTION_DATE=2022-10-04T17:55:58.781085+00:00
AIRFLOW_CTX_DAG_RUN_ID=manual__2022-10-04T17:55:58.781085+00:00
[2022-10-04 17:56:11,594] {taskinstance.py:1700} ERROR - Task failed with exception
Traceback (most recent call last):
  File "/home/airflow/.local/lib/python3.7/site-packages/airflow/models/taskinstance.py", line 1329, in _run_raw_task
    self._execute_task_with_callbacks(context)
  File "/home/airflow/.local/lib/python3.7/site-packages/airflow/models/taskinstance.py", line 1455, in _execute_task_with_callbacks
    result = self._execute_task(context, self.task)
  File "/home/airflow/.local/lib/python3.7/site-packages/airflow/models/taskinstance.py", line 1511, in _execute_task
    result = execute_callable(context=context)
  File "/home/airflow/.local/lib/python3.7/site-packages/airflow/operators/python.py", line 174, in execute
    return_value = self.execute_callable()
  File "/home/airflow/.local/lib/python3.7/site-packages/airflow/operators/python.py", line 185, in execute_callable
    return self.python_callable(*self.op_args, **self.op_kwargs)
  File "/opt/airflow/dags/data_ingestion_gcs_dag.py", line 64, in upload_to_gcs
    blob.upload_from_filename(local_file) # uploads file that it is supposed to uplooad to a target location
  File "/home/airflow/.local/lib/python3.7/site-packages/google/cloud/storage/blob.py", line 2735, in upload_from_filename
    retry=retry,
  File "/home/airflow/.local/lib/python3.7/site-packages/google/cloud/storage/blob.py", line 2594, in upload_from_file
    retry=retry,
  File "/home/airflow/.local/lib/python3.7/site-packages/google/cloud/storage/blob.py", line 2396, in _do_upload
    retry=retry,
  File "/home/airflow/.local/lib/python3.7/site-packages/google/cloud/storage/blob.py", line 1874, in _do_multipart_upload
    hostname=hostname, bucket_path=self.bucket.path
  File "/home/airflow/.local/lib/python3.7/site-packages/google/cloud/storage/bucket.py", line 1098, in path
    raise ValueError("Cannot determine path without bucket name.")
ValueError: Cannot determine path without bucket name.
[2022-10-04 17:56:11,619] {taskinstance.py:1277} INFO - Marking task as UP_FOR_RETRY. dag_id=data_ingestion_gcs_dag, task_id=local_to_gcs_task, execution_date=20221004T175558, start_date=20221004T175611, end_date=20221004T175611
[2022-10-04 17:56:11,641] {standard_task_runner.py:92} ERROR - Failed to execute job 21 for task local_to_gcs_task
Traceback (most recent call last):
  File "/home/airflow/.local/lib/python3.7/site-packages/airflow/task/task_runner/standard_task_runner.py", line 85, in _start_by_fork
    args.func(args, dag=self.dag)
  File "/home/airflow/.local/lib/python3.7/site-packages/airflow/cli/cli_parser.py", line 48, in command
    return func(*args, **kwargs)
  File "/home/airflow/.local/lib/python3.7/site-packages/airflow/utils/cli.py", line 92, in wrapper
    return f(*args, **kwargs)
  File "/home/airflow/.local/lib/python3.7/site-packages/airflow/cli/commands/task_command.py", line 298, in task_run
    _run_task_by_selected_method(args, dag, ti)
  File "/home/airflow/.local/lib/python3.7/site-packages/airflow/cli/commands/task_command.py", line 107, in _run_task_by_selected_method
    _run_raw_task(args, ti)
  File "/home/airflow/.local/lib/python3.7/site-packages/airflow/cli/commands/task_command.py", line 184, in _run_raw_task
    error_file=args.error_file,
  File "/home/airflow/.local/lib/python3.7/site-packages/airflow/utils/session.py", line 70, in wrapper
    return func(*args, session=session, **kwargs)
  File "/home/airflow/.local/lib/python3.7/site-packages/airflow/models/taskinstance.py", line 1329, in _run_raw_task
    self._execute_task_with_callbacks(context)
  File "/home/airflow/.local/lib/python3.7/site-packages/airflow/models/taskinstance.py", line 1455, in _execute_task_with_callbacks
    result = self._execute_task(context, self.task)
  File "/home/airflow/.local/lib/python3.7/site-packages/airflow/models/taskinstance.py", line 1511, in _execute_task
    result = execute_callable(context=context)
  File "/home/airflow/.local/lib/python3.7/site-packages/airflow/operators/python.py", line 174, in execute
    return_value = self.execute_callable()
  File "/home/airflow/.local/lib/python3.7/site-packages/airflow/operators/python.py", line 185, in execute_callable
    return self.python_callable(*self.op_args, **self.op_kwargs)
  File "/opt/airflow/dags/data_ingestion_gcs_dag.py", line 64, in upload_to_gcs
    blob.upload_from_filename(local_file) # uploads file that it is supposed to uplooad to a target location
  File "/home/airflow/.local/lib/python3.7/site-packages/google/cloud/storage/blob.py", line 2735, in upload_from_filename
    retry=retry,
  File "/home/airflow/.local/lib/python3.7/site-packages/google/cloud/storage/blob.py", line 2594, in upload_from_file
    retry=retry,
  File "/home/airflow/.local/lib/python3.7/site-packages/google/cloud/storage/blob.py", line 2396, in _do_upload
    retry=retry,
  File "/home/airflow/.local/lib/python3.7/site-packages/google/cloud/storage/blob.py", line 1874, in _do_multipart_upload
    hostname=hostname, bucket_path=self.bucket.path
  File "/home/airflow/.local/lib/python3.7/site-packages/google/cloud/storage/bucket.py", line 1098, in path
    raise ValueError("Cannot determine path without bucket name.")
ValueError: Cannot determine path without bucket name.
[2022-10-04 17:56:11,679] {local_task_job.py:154} INFO - Task exited with return code 1
[2022-10-04 17:56:11,745] {local_task_job.py:264} INFO - 0 downstream tasks scheduled from follow-on schedule check
