[2022-10-04 18:15:05,344] {taskinstance.py:1032} INFO - Dependencies all met for <TaskInstance: data_ingestion_gcs_dag.local_to_gcs_task manual__2022-10-04T18:14:52.362783+00:00 [queued]>
[2022-10-04 18:15:05,363] {taskinstance.py:1032} INFO - Dependencies all met for <TaskInstance: data_ingestion_gcs_dag.local_to_gcs_task manual__2022-10-04T18:14:52.362783+00:00 [queued]>
[2022-10-04 18:15:05,363] {taskinstance.py:1238} INFO - 
--------------------------------------------------------------------------------
[2022-10-04 18:15:05,363] {taskinstance.py:1239} INFO - Starting attempt 1 of 2
[2022-10-04 18:15:05,363] {taskinstance.py:1240} INFO - 
--------------------------------------------------------------------------------
[2022-10-04 18:15:05,382] {taskinstance.py:1259} INFO - Executing <Task(PythonOperator): local_to_gcs_task> on 2022-10-04 18:14:52.362783+00:00
[2022-10-04 18:15:05,392] {standard_task_runner.py:52} INFO - Started process 4296 to run task
[2022-10-04 18:15:05,397] {standard_task_runner.py:76} INFO - Running: ['***', 'tasks', 'run', 'data_ingestion_gcs_dag', 'local_to_gcs_task', 'manual__2022-10-04T18:14:52.362783+00:00', '--job-id', '29', '--raw', '--subdir', 'DAGS_FOLDER/data_ingestion_gcs_dag.py', '--cfg-path', '/tmp/tmpr9mw_ee3', '--error-file', '/tmp/tmp6gmkblox']
[2022-10-04 18:15:05,399] {standard_task_runner.py:77} INFO - Job 29: Subtask local_to_gcs_task
[2022-10-04 18:15:05,481] {logging_mixin.py:109} INFO - Running <TaskInstance: data_ingestion_gcs_dag.local_to_gcs_task manual__2022-10-04T18:14:52.362783+00:00 [running]> on host 3adc7691bbaa
[2022-10-04 18:15:05,576] {taskinstance.py:1426} INFO - Exporting the following env vars:
AIRFLOW_CTX_DAG_OWNER=***
AIRFLOW_CTX_DAG_ID=data_ingestion_gcs_dag
AIRFLOW_CTX_TASK_ID=local_to_gcs_task
AIRFLOW_CTX_EXECUTION_DATE=2022-10-04T18:14:52.362783+00:00
AIRFLOW_CTX_DAG_RUN_ID=manual__2022-10-04T18:14:52.362783+00:00
[2022-10-04 18:15:05,607] {taskinstance.py:1700} ERROR - Task failed with exception
Traceback (most recent call last):
  File "/home/airflow/.local/lib/python3.7/site-packages/airflow/models/taskinstance.py", line 1329, in _run_raw_task
    self._execute_task_with_callbacks(context)
  File "/home/airflow/.local/lib/python3.7/site-packages/airflow/models/taskinstance.py", line 1455, in _execute_task_with_callbacks
    result = self._execute_task(context, self.task)
  File "/home/airflow/.local/lib/python3.7/site-packages/airflow/models/taskinstance.py", line 1511, in _execute_task
    result = execute_callable(context=context)
  File "/home/airflow/.local/lib/python3.7/site-packages/airflow/operators/python.py", line 174, in execute
    return_value = self.execute_callable()
  File "/home/airflow/.local/lib/python3.7/site-packages/airflow/operators/python.py", line 185, in execute_callable
    return self.python_callable(*self.op_args, **self.op_kwargs)
  File "/opt/airflow/dags/data_ingestion_gcs_dag.py", line 64, in upload_to_gcs
    blob.upload_from_filename(local_file) # uploads file that it is supposed to uplooad to a target location
  File "/home/airflow/.local/lib/python3.7/site-packages/google/cloud/storage/blob.py", line 2735, in upload_from_filename
    retry=retry,
  File "/home/airflow/.local/lib/python3.7/site-packages/google/cloud/storage/blob.py", line 2594, in upload_from_file
    retry=retry,
  File "/home/airflow/.local/lib/python3.7/site-packages/google/cloud/storage/blob.py", line 2396, in _do_upload
    retry=retry,
  File "/home/airflow/.local/lib/python3.7/site-packages/google/cloud/storage/blob.py", line 1874, in _do_multipart_upload
    hostname=hostname, bucket_path=self.bucket.path
  File "/home/airflow/.local/lib/python3.7/site-packages/google/cloud/storage/bucket.py", line 1098, in path
    raise ValueError("Cannot determine path without bucket name.")
ValueError: Cannot determine path without bucket name.
[2022-10-04 18:15:05,631] {taskinstance.py:1277} INFO - Marking task as UP_FOR_RETRY. dag_id=data_ingestion_gcs_dag, task_id=local_to_gcs_task, execution_date=20221004T181452, start_date=20221004T181505, end_date=20221004T181505
[2022-10-04 18:15:05,654] {standard_task_runner.py:92} ERROR - Failed to execute job 29 for task local_to_gcs_task
Traceback (most recent call last):
  File "/home/airflow/.local/lib/python3.7/site-packages/airflow/task/task_runner/standard_task_runner.py", line 85, in _start_by_fork
    args.func(args, dag=self.dag)
  File "/home/airflow/.local/lib/python3.7/site-packages/airflow/cli/cli_parser.py", line 48, in command
    return func(*args, **kwargs)
  File "/home/airflow/.local/lib/python3.7/site-packages/airflow/utils/cli.py", line 92, in wrapper
    return f(*args, **kwargs)
  File "/home/airflow/.local/lib/python3.7/site-packages/airflow/cli/commands/task_command.py", line 298, in task_run
    _run_task_by_selected_method(args, dag, ti)
  File "/home/airflow/.local/lib/python3.7/site-packages/airflow/cli/commands/task_command.py", line 107, in _run_task_by_selected_method
    _run_raw_task(args, ti)
  File "/home/airflow/.local/lib/python3.7/site-packages/airflow/cli/commands/task_command.py", line 184, in _run_raw_task
    error_file=args.error_file,
  File "/home/airflow/.local/lib/python3.7/site-packages/airflow/utils/session.py", line 70, in wrapper
    return func(*args, session=session, **kwargs)
  File "/home/airflow/.local/lib/python3.7/site-packages/airflow/models/taskinstance.py", line 1329, in _run_raw_task
    self._execute_task_with_callbacks(context)
  File "/home/airflow/.local/lib/python3.7/site-packages/airflow/models/taskinstance.py", line 1455, in _execute_task_with_callbacks
    result = self._execute_task(context, self.task)
  File "/home/airflow/.local/lib/python3.7/site-packages/airflow/models/taskinstance.py", line 1511, in _execute_task
    result = execute_callable(context=context)
  File "/home/airflow/.local/lib/python3.7/site-packages/airflow/operators/python.py", line 174, in execute
    return_value = self.execute_callable()
  File "/home/airflow/.local/lib/python3.7/site-packages/airflow/operators/python.py", line 185, in execute_callable
    return self.python_callable(*self.op_args, **self.op_kwargs)
  File "/opt/airflow/dags/data_ingestion_gcs_dag.py", line 64, in upload_to_gcs
    blob.upload_from_filename(local_file) # uploads file that it is supposed to uplooad to a target location
  File "/home/airflow/.local/lib/python3.7/site-packages/google/cloud/storage/blob.py", line 2735, in upload_from_filename
    retry=retry,
  File "/home/airflow/.local/lib/python3.7/site-packages/google/cloud/storage/blob.py", line 2594, in upload_from_file
    retry=retry,
  File "/home/airflow/.local/lib/python3.7/site-packages/google/cloud/storage/blob.py", line 2396, in _do_upload
    retry=retry,
  File "/home/airflow/.local/lib/python3.7/site-packages/google/cloud/storage/blob.py", line 1874, in _do_multipart_upload
    hostname=hostname, bucket_path=self.bucket.path
  File "/home/airflow/.local/lib/python3.7/site-packages/google/cloud/storage/bucket.py", line 1098, in path
    raise ValueError("Cannot determine path without bucket name.")
ValueError: Cannot determine path without bucket name.
[2022-10-04 18:15:05,690] {local_task_job.py:154} INFO - Task exited with return code 1
[2022-10-04 18:15:05,758] {local_task_job.py:264} INFO - 0 downstream tasks scheduled from follow-on schedule check
